Workbook

Sheet Calculator
A1: HOT-STEP • LoRA TRAINING DASHBOARD
A2: Dataset-aware training recommendations • edit the blue/yellow fields • green values are calculated
A3: INPUTS • describe your dataset | F3: RECOMMENDED SETTINGS • ready to copy into the trainer
A4: Start with Dataset + Training choices. After a trial, enter feedback and the best checkpoint; calibration is optional.
A5: 1 DATASET | F5: LORA RANK | H5: TRAINING STEPS | J5: ALPHA
A6: Input | B6: Your value | C6: Allowed | D6: Notes & tips | F6: =B32 -> 64 | H6: =B35 -> 380 | J6: =B33 -> 64
A7: Number of tracks | B7: 10 | C7: whole number, 1 or more | D7: How many separate songs are in the dataset. Count the ORIGINAL songs, not the clips they were cut into. TIP: this is the biggest single driver of steps, rank and learning rate. Small datasets get a smaller rank and higher caption dropout.
A8: Total audio time (minutes) | B8: 63.749338 | C8: number above 0 | D8: The combined length of ALL tracks in minutes (for example 38 tracks x about 4 minutes = 152). TIP: check the folder's total duration in your file manager. A rough figure is fine; longer datasets raise the steps a little.
A9: Music complexity (1 - 10) | B9: 8 | C9: dropdown 1 to 10 | D9: How busy and layered the music is. 1 = sparse (a voice and one instrument), 10 = multi-layered, complicated music. TIP: see the Guides sheet for examples at each level. If unsure, listen to three random tracks and rate the busiest one. Complexity drives steps, rank, learning rate, planner scale, timing weight and the decay shape. | F9: LEARNING RATE | H9: TIMING WEIGHT | J9: DROPOUT
A10: Tag quality (1 - 10) [legacy fallback] | B10: 8 | C10: dropdown 1 to 10 | D10: Legacy fallback only. If Average caption tags / track is filled, the latest Python v2 tag-count formula is used instead. | F10: =B37 -> 7e-05 | H10: =B34 -> 0.12 | J10: =B39 -> 0.5
A11: Tracks split into short clips? | B11: No | C11: Yes / No | D11: Did you cut the songs into short clips for training? TIP: Yes (or having fewer than 15 tracks) sets caption dropout to 0.50 to stop the model memorising captions; otherwise it is 0.35.
A12: Average caption tags / track [Python v2] | B12: 28 | C12: number, 0+ | D12: Latest Python method: count comma-separated tags in every <track>.yue2.txt and average over ALL tracks; tracks without a caption count as 0. 28+ gives the maximum caption richness factor (1.30). | F12: AUDIO COMPLEXITY [Python/DSP] | G12: 1.288333 | H12: CAPTION FACTOR [Python v2] | I12: =Engine!B10 -> 1.3
A13: 2 TRAINING CHOICES | F13: DATASET PROFILE
A14: Input | B14: Your value | C14: Allowed | D14: Notes & tips | F14: Tracks | H14: Minutes | J14: Complexity
A15: Optimizer | B15: AdamW | C15: dropdown | D15: The optimizer you train with. TIP: Prodigy and Muon manage the learning rate themselves, so the learning rate result shows 'engine default' for them. | F15: =B7 -> 10 | H15: =B8 -> 63.749338 | J15: =B9 -> 8
A16: Accumulation steps | B16: 1 | C16: whole number 1 to 64 | D16: Gradient accumulation steps in your trainer (1 if you do not use it). TIP: the learning rate is divided by the square root of this number. If you change it later, re-copy the new learning rate. | F16: Tag quality | H16: Clips | J16: Optimizer
A17: Decay shape | B17: Auto | C17: Auto / Cosine / Linear | D17: How the learning rate falls during the final decay phase. TIP: leave on Auto. Auto picks Linear for very busy music (complexity 7 or more), otherwise Cosine. With an active calibration, Auto uses the shape from your calibration run. | F17: =B10 -> 8 | H17: =B11 -> No | J17: =B15 -> AdamW
A19: 3 TRIAL FEEDBACK | F19: TRIAL + CALIBRATION STATUS
A20: Input | B20: Your value | C20: Allowed | D20: Notes & tips | F20: =IF(AND(B21="Good",OR(B22="Good",B22="NA"),B23=0),"FIRST RUN • no feedback applied","FEEDBACK • "&IF(B23>0,"peak step "&B23&" • ","")&"Instruments: "&B21&" • Vocals: "&B22) -> FIRST RUN • no feedback applied
A21: Instruments sound | B21: Good | C21: Good / Weak / Overcooked | D21: How do the instruments in your test generations sound compared with the dataset? Good = close, good timbre. Weak = lacks character. Overcooked = near-exact copies / memorised. TIP: Weak raises rank and learning rate. Overcooked lowers rank, raises caption dropout to 0.50 and lengthens the decay.
A22: Vocals sound | B22: Good | C22: Good / Weak / Overcooked / NA | D22: How do the vocals sound compared with the singer in the dataset? Choose NA for instrumental datasets. TIP: Weak raises rank. Overcooked lowers the learning rate and raises caption dropout to 0.50. | F22: =IF(B27="Yes","CALIBRATION ON • "&Calibration!B7,"CALIBRATION OFF") -> CALIBRATION ON • Ryk 1.10
A23: Best peak step (0 = first run) | B23: 0 | C23: whole number, 0 or more | D23: The checkpoint step that sounded best in your trial run. Leave 0 on the first run. TIP: save checkpoints often (for example every 25 to 50 steps) so you can find the peak. Entering it re-fits the schedule so the peak sits at the end of the stable phase and the decay follows.
A25: 4 CALIBRATION | F25: TRAINER COPY BLOCK
A26: Input | B26: Your value | C26: Allowed | D26: Notes & tips | F26: Rank | I26: =B32 -> 64
A27: Apply calibration? | B27: Yes | C27: Yes / No | D27: Yes = correct the calculator using the run you entered on the Calibration sheet. TIP: fill in the Calibration sheet first (a dataset the calculator got wrong, plus the settings that worked), then switch this to Yes. Keep it on No for the plain calculation. | F27: Alpha | I27: =B33 -> 64
A28: Calibration in use | B28: =IF(B27="Yes",IF(Calibration!B7<>"","Run: "&Calibration!B7,"(no run name entered)"),"Off") -> Run: Ryk 1.10 | C28: (shows automatically) | D28: Shows which calibration run is being applied, using the Run name from the Calibration sheet. | F28: Steps | I28: =B35 -> 380
F29: Optimizer | I29: =B36 -> AdamW
A30: 5 RECOMMENDED SETTINGS | F30: Learning Rate | I30: =B37 -> 7e-05
A31: Setting | B31: Value | C31: Unit / range | D31: What it is & tips | F31: Planner LR Scale | I31: =B38 -> 0.47
A32: Lora Rank | B32: =Engine!B49 -> 64 | C32: 8, 16, 32, 64, 128 or 256 | D32: LoRA rank. Always one of the valid sizes. TIP: if you run out of VRAM, step down one size; if the result is too weak, step up one. | F32: Caption Dropout | I32: =B39 -> 0.5
A33: Alpha | B33: =Engine!B50 -> 64 | C33: usually equal to rank | D33: LoRA alpha. Equals the rank unless a calibration run used a different ratio. TIP: keep alpha equal to rank for standard scaling. | F33: Decay Steps | I33: =B40 -> 140
A34: Timing Loss Weight | B34: =Engine!B52 -> 0.12 | C34: about 0.05 to 0.15 | D34: How strongly timing is weighted in the loss. Busier music gets a slightly higher value. | F34: Decay Shape | I34: =B41 -> Cosine
A35: Steps | B35: =Engine!B43 -> 380 | C35: total training steps | D35: Total training steps. TIP: save checkpoints often and enter the best one in section 3 for the next calculation. | F35: Accumulation | I35: =B42 -> 1
A36: Optimizer | B36: =B15 -> AdamW | C36: as chosen | D36: The optimizer you selected in section 2, repeated here so you can copy all settings from one block.
A37: Learning Rate | B37: =Engine!B47 -> 7e-05 | C37: per-step learning rate | D37: The learning rate to enter in the trainer, already adjusted for your accumulation steps. 'engine default' means the optimizer sets it itself. | F37: WHY THESE NUMBERS?
A38: Planner Learning-Rate Scale | B38: =Engine!B51 -> 0.47 | C38: about 0.20 to 0.50 | D38: Scale for the planner's learning rate. Higher for busier music. | F38: Combined complexity | I38: =Engine!B11 -> 1.6748328
A39: Caption Dropout | B39: =Engine!B54 -> 0.5 | C39: 0 to 0.9 | D39: Fraction of training steps where the caption is dropped. Higher values reduce caption memorisation. TIP: if generations just copy the training songs (Overcooked), this goes to 0.50 or higher automatically. | F39: Audio complexity score | I39: =Engine!B9 -> 1.288333
A40: Decay Steps | B40: =Engine!B44 -> 140 | C40: steps in the final decay phase | D40: Number of steps in the final decay phase of the schedule (about 40% of the run unless calibration or feedback changes it). | F40: Caption richness | I40: =Engine!B10 -> 1.3
A41: Decay Shape | B41: =Engine!B55 -> Cosine | C41: Cosine / Linear | D41: Shape of the learning-rate decay. Cosine is gentler; Linear cools steadily across busy, mixed material. | F41: Dataset-size curve | I41: =Engine!B16 -> 0.11072732
A42: Accumulation Steps | B42: =B16 -> 1 | C42: as chosen | D42: Gradient accumulation steps, repeated from section 2. | F42: Decay shape | I42: =B41 -> Cosine
...

Sheet Calibration
A1: Calibration - teach the calculator what worked
A2: This sheet is seeded from the Python calibration.cfg run Ryk 1.10. The exact Python baseline/worked datum is retained below so the calculator starts from the same calibration point.
A3: Legend: | B3: Yellow + blue text = you edit | C3: Green = calculated | D3: Python calibration imported: Ryk 1.10
A5: A. THE DATASET THE SETTINGS WORKED ON
A6: Input | B6: Your value | C6: Allowed | D6: Notes & tips
A7: Run name | B7: Ryk 1.10 | C7: any text | D7: A name for this calibration. It is shown on the Calculator sheet when calibration is in use. TIP: use something you will recognise, such as the singer or album.
A8: Dataset name | B8: Royksopp Select 10 v4 | C8: any text (record only) | D8: The folder or dataset name. Kept for your records; it does not change any calculation.
A9: Number of tracks | B9: 10 | C9: whole number, 1 or more | D9: How many songs were in THAT dataset (the one the settings worked on).
A10: Total audio time (minutes) | B10: 63.749338 | C10: number above 0 | D10: Combined length of all tracks in that dataset, in minutes.
A11: Music complexity (1 - 10) | B11: 10 | C11: dropdown 1 to 10 | D11: Rate that dataset's music with the same scale as the Calculator sheet (see the Guides sheet).
A12: Tag quality (1 - 10) | B12: 10 | C12: dropdown 1 to 10 | D12: Rate that dataset's captions with the same scale as the Calculator sheet.
A13: Tracks split into short clips? | B13: No | C13: Yes / No | D13: Were that dataset's songs cut into clips?
A15: B. THE SETTINGS THAT WORKED
A16: Setting | B16: What worked | C16: Allowed | D16: Notes & tips
A17: Rank | B17: 64 | C17: 8, 16, 32, 64, 128, 256 | D17: The LoRA rank that gave good results. TIP: this is the setting most likely to differ from the calculator's figure.
A18: Alpha | B18: 64 | C18: number above 0 | D18: The LoRA alpha you used. Usually the same as the rank.
A19: Timing loss weight | B19: 0.12 | C19: about 0.05 to 0.15 | D19: The timing loss weight you used.
A20: Steps (total) | B20: 380 | C20: whole number | D20: The total number of steps of the run length you want repeated. TIP: if your best checkpoint was well before the end, enter the shorter length you would use next time.
A21: Learning rate (as entered) | B21: 7e-05 | C21: number above 0 | D21: The learning rate you typed into the trainer, as is. TIP: leave blank if you used Prodigy or Muon.
A22: Accumulation steps used | B22: 1 | C22: whole number, 1 or more | D22: The accumulation you used with that learning rate. It is needed to compare learning rates fairly.
A23: Planner learning-rate scale | B23: 0.47 | C23: about 0.20 to 0.50 | D23: The planner learning-rate scale you used.
A24: Caption dropout | B24: 0.5 | C24: 0 to 0.9 | D24: The caption dropout you used.
A25: Average caption tags / track (Python v2) | B25: 28 | C25: number, 0+ | D25: The Ryk 1.10 datum uses the latest Python caption calculation. 28+ tags produces the maximum richness factor of 1.30.
A26: Decay shape | B26: Cosine | C26: Cosine / Linear | D26: The decay shape you used.
A28: C. ANALYSER RESULTS FOR THAT RUN (for your records - they do not change the calculation)
A29: Item | B29: Your value | C29: Allowed | D29: Notes & tips
A30: Best checkpoint step | B30: 375 | C30: whole number | D30: Which checkpoint your analyser or ears judged best. TIP: if this is far below the total steps, consider using the shorter length in B.
A31: Singer score | B31: 0.8 | C31: number | D31: Voice-match score from your comparison tool, if you have one.
A32: Vibe score | B32: 0.74 | C32: number | D32: Overall sound-match score from your comparison tool, if you have one.
A33: Instruments verdict | B33: Good | C33: Good / Weak / Overcooked / NA | D33: Your judgement of the instruments at the best checkpoint.
A34: Vocals verdict | B34: Good | C34: Good / Weak / Overcooked / NA | D34: Your judgement of the vocals at the best checkpoint.
A36: D. PYTHON CALIBRATION DATUM (from calibration.cfg)
A37: Baseline learning rate | B37: 6.0913049e-05 | C37: Python datum before calibration correction | D37: What it means
A38: Baseline rank | B38: 38.302851 | C38: Python datum before calibration correction | D38: Multiplier on the plain learning rate. Compared before accumulation scaling so runs with different accumulation stay comparable.
A39: Baseline peak step | B39: 366 | C39: Python datum | D39: Multiplier on the plain rank capacity. The result is then rounded to a valid rank (8, 16, 32, 64, 128, 256).
A40: Baseline timing loss weight | B40: 0.12 | C40: Python datum | D40: Multiplier on the plain total steps. On the calibration dataset itself this reproduces your steps exactly.
A41: Baseline planner scale | B41: 0.47 | C41: Python datum | D41: Multiplier on the plain timing loss weight.
A42: Baseline caption dropout | B42: 0.5 | C42: Python datum | D42: Multiplier on the plain planner scale.
A43: Worked total steps | B43: 380 | C43: Python datum | D43: Added to the plain dropout (a shift, not a multiplier).
A44: Worked decay steps | B44: 140 | C44: Python datum | D44: Decay steps divided by total steps. Applied to the total steps of any dataset.
...

Sheet Guides
A1: Guides - how to rate your dataset and what the calculator does
A3: MUSIC COMPLEXITY (1 - 10)
A4: Rating | B4: What it sounds like | C4: Audio complexity score
A5: 1 | B5: Sparse: a voice with one quiet instrument, slow, almost nothing changing. | C5: =0.6+(A5-1)/9 -> 0.6
A6: 2 | B6: Very simple: voice plus one instrument (acoustic guitar or piano), steady dynamics. | C6: =0.6+(A6-1)/9 -> 0.71111111
A7: 3 | B7: Simple: small band or minimal electronic, only a few layers. | C7: =0.6+(A7-1)/9 -> 0.82222222
A8: 4 | B8: Moderate: a standard pop or rock arrangement with a clean mix. | C8: =0.6+(A8-1)/9 -> 0.93333333
A9: 5 | B9: Typical full track: drums, bass, chords, a lead and a vocal, some variation. | C9: =0.6+(A9-1)/9 -> 1.0444444
A10: 6 | B10: Fairly busy: many layers, some fast changes and effects. | C10: =0.6+(A10-1)/9 -> 1.1555556
A11: 7 | B11: Dense: lots of synth layers, stereo effects and frequent transients (typical modern synthpop or dance music). | C11: =0.6+(A11-1)/9 -> 1.2666667
A12: 8 | B12: Very dense: heavily layered, wide frequency range, rapid changes. | C12: =0.6+(A12-1)/9 -> 1.3777778
A13: 9 | B13: Extremely layered: sound-design heavy with constant movement. | C13: =0.6+(A13-1)/9 -> 1.4888889
A14: 10 | B14: Maximum: multi-layered, complicated music throughout (orchestral plus electronic, glitch, breakcore). | C14: =0.6+(A14-1)/9 -> 1.6
A16: TAG QUALITY (1 - 10, 10 is best)
A17: Rating | B17: What the captions look like | C17: Caption richness factor | D17: About this many tags
A18: 1 | B18: Missing, or a single genre word. | C18: =0.8+0.5*(A18-1)/9 -> 0.8 | D18: =ROUND(4+24*(A18-1)/9,0) -> 4
A19: 2 | B19: Genre plus one or two words. | C19: =0.8+0.5*(A19-1)/9 -> 0.85555556 | D19: =ROUND(4+24*(A19-1)/9,0) -> 7
A20: 3 | B20: Genre, mood and BPM only. | C20: =0.8+0.5*(A20-1)/9 -> 0.91111111 | D20: =ROUND(4+24*(A20-1)/9,0) -> 9
A21: 4 | B21: Genre plus a few instruments. | C21: =0.8+0.5*(A21-1)/9 -> 0.96666667 | D21: =ROUND(4+24*(A21-1)/9,0) -> 12
A22: 5 | B22: Genre, main instruments and mood. | C22: =0.8+0.5*(A22-1)/9 -> 1.0222222 | D22: =ROUND(4+24*(A22-1)/9,0) -> 15
A23: 6 | B23: Genre, instruments, mood and a little about the vocal. | C23: =0.8+0.5*(A23-1)/9 -> 1.0777778 | D23: =ROUND(4+24*(A23-1)/9,0) -> 17
A24: 7 | B24: Instruments, vocal style, mix and mood described. | C24: =0.8+0.5*(A24-1)/9 -> 1.1333333 | D24: =ROUND(4+24*(A24-1)/9,0) -> 20
A25: 8 | B25: Detailed: instruments, vocal processing, mix, mood and BPM. | C25: =0.8+0.5*(A25-1)/9 -> 1.1888889 | D25: =ROUND(4+24*(A25-1)/9,0) -> 23
A26: 9 | B26: Very detailed on every part of the sound. | C26: =0.8+0.5*(A26-1)/9 -> 1.2444444 | D26: =ROUND(4+24*(A26-1)/9,0) -> 25
A27: 10 | B27: Best: about 28 specific tags covering genre, instruments, vocal delivery, effects, mix, mood and BPM. | C27: =0.8+0.5*(A27-1)/9 -> 1.3 | D27: =ROUND(4+24*(A27-1)/9,0) -> 28
A28: TIP: tags per track are what count. The desktop calculator counts the comma-separated tags in each <trackname>.yue2.txt file; 1 = about 4 tags or fewer, 10 = about 28 tags or more. Tracks with no caption pull the average down.
A30: WHAT EACH INPUT CHANGES
A31: Input | B31: Effect
A32: Tracks | B32: Main driver of steps, learning rate and rank. Also sets caption dropout (fewer than 15 tracks = 0.50).
A33: Total time | B33: Raises the steps a little as the dataset gets longer.
A34: Complexity | B34: Raises steps, learning rate and rank; also sets planner scale, timing loss weight and (with Auto) the decay shape.
A35: Tag quality | B35: Raises steps, learning rate (about +28% from poorest to best tags) and rank capacity. Planner scale, timing weight, dropout and decay shape are not affected.
A36: Instruments Weak | B36: Rank x1.25 and learning rate x1.15.
A37: Instruments Overcooked | B37: Rank x0.75, caption dropout to 0.50, decay 5% longer.
A38: Vocals Weak | B38: Rank x1.20.
A39: Vocals Overcooked | B39: Learning rate x0.85 and caption dropout to 0.50.
A40: Best peak step | B40: Total steps re-fitted so the peak sits at the end of the stable phase (about 60% of the run), with the decay after it.
A41: Accumulation | B41: Learning rate divided by the square root of the accumulation steps.
A42: Optimizer | B42: Prodigy and Muon show 'engine default' for the learning rate.
A43: Calibration | B43: Multiplies the plain steps, learning rate, rank, timing weight and planner scale by the factors on the Calibration sheet.
...

Sheet Engine
A1: Engine - workings (do not edit) | E1: Python datum | F1: Exact factors
A2: Column B calculates your dataset on the Calculator sheet. Column C calculates the Calibration dataset on the same formulas, so the Calibration sheet can compare 'what the plain calculator says' with 'what worked'. | E2: =Calibration!B37 -> 6.0913049e-05 | F2: =IFERROR(Calibration!B45/Calibration!B37,1) -> 1.1491791
A3: Item | B3: Your dataset | C3: Calibration dataset | D3: Meaning | E3: =Calibration!B38 -> 38.302851 | F3: =IFERROR(Calibration!B46/Calibration!B38,1) -> 1.6708939
A4: Number of tracks | B4: =Calculator!B7 -> 10 | C4: =Calibration!B9 -> 10 | D4: Input | E4: =Calibration!B40 -> 0.12 | F4: =IFERROR(Calibration!B43/(Calibration!B39/0.6),1) -> 0.62295082
A5: Total minutes | B5: =Calculator!B8 -> 63.749338 | C5: =Calibration!B10 -> 63.749338 | D5: Input | E5: =Calibration!B41 -> 0.47 | F5: =IFERROR(Calibration!B48/Calibration!B40,1) -> 1
A6: Complexity rating | B6: =Calculator!B9 -> 8 | C6: =Calibration!B11 -> 10 | D6: Input (1-10) | E6: =Calibration!B42 -> 0.5 | F6: =IFERROR(Calibration!B49/Calibration!B41,1) -> 1
A7: Tag quality rating (legacy) | B7: =Calculator!B10 -> 8 | C7: =Calibration!B12 -> 10 | D7: Input (1-10) | E7: =Calibration!B43 -> 380 | F7: =IFERROR(Calibration!B50-Calibration!B42,0) -> 0
A8: Split into clips? | B8: =Calculator!B11 -> No | C8: =Calibration!B13 -> No | D8: Input (Yes/No) | E8: =Calibration!B44 -> 140 | F8: =IFERROR(Calibration!B44/Calibration!B43,"") -> 0.36842105
A9: Audio complexity score | B9: =IF(ISNUMBER(Calculator!G12),Calculator!G12,0.6+(B6-1)/9) -> 1.288333 | C9: =Calibration!B51 -> 1.288333 | D9: Python/DSP audio complexity when Calculator!G12 is populated; otherwise the legacy 1–10 proxy is used. | E9: =Calibration!B45 -> 7e-05 | F9: =IFERROR(Calibration!B47/Calibration!B46,1) -> 1
A10: Caption richness factor (Python v2) | B10: =IF(ISNUMBER(Calculator!B12),0.8+0.5*MAX(0,MIN((Calculator!B12-4)/24,1)),0.8+0.5*(B7-1)/9) -> 1.3 | C10: =IF(ISNUMBER(Calibration!B25),0.8+0.5*MAX(0,MIN((Calibration!B25-4)/24,1)),0.8+0.5*(C7-1)/9) -> 1.3 | D10: Latest Python v2: 0.80 + 0.50 × clamp((average tags − 4) / 24, 0, 1). Average is across ALL tracks. | E10: 64
A11: Combined complexity (Python v2) | B11: =B9*B10 -> 1.6748328 | C11: =C9*C10 -> 1.6748328 | D11: Audio complexity × Python caption richness factor. | E11: 64
A12: Spectral variance score | B12: =(B6-1)/9 -> 0.77777778 | C12: =(C6-1)/9 -> 1 | D12: Legacy spreadsheet proxy only; the Python engine derives variance from measured spectral flux/centroid/RMS. | E12: 0.12
A13: Duration (hours) | B13: =MAX(0.05,B5/60) -> 1.062489 | C13: =MAX(0.05,C5/60) -> 1.062489 | D13: Minutes / 60, at least 0.05 | E13: 0.47
A14: Base steps | B14: =150+130*LN(MAX(2,B4)*B11*(1+0.2*LN(1+B13))) -> 533.95673 | C14: =150+130*LN(MAX(2,C4)*C11*(1+0.2*LN(1+C13))) -> 533.95673 | D14: 150 + 130 x ln(tracks x complexity x duration term) | E14: 0.5
A15: Plain total steps | B15: =ROUND(B14*1.15/10,0)*10 -> 610 | C15: 610 | D15: Base steps x 1.15, rounded to 10 | E15: =Calibration!B64 -> Cosine
A16: Dataset-size curve | B16: =1/(1+EXP(-(B4-35)/12)) -> 0.11072732 | C16: =1/(1+EXP(-(C4-35)/12)) -> 0.11072732 | D16: Smooth step centred on 35 tracks | E16: 1.6748328
A17: Plain learning rate (before accumulation) | B17: =(0.000028+0.000062*B16)*SQRT(B11)*1.35 -> 6.0913049e-05 | C17: 6.0913049e-05 | D17: Rises with dataset size and sqrt(complexity) | E17: 610
A18: Volume term | B18: =LOG(MAX(2,B4/3),2) -> 1.7369656 | C18: =LOG(MAX(2,C4/3),2) -> 1.7369656 | D18: log2(tracks / 3)
A19: Rank capacity | B19: =(5.5+10*B18)*B11 -> 38.302851 | C19: =(5.5+10*C18)*C11 -> 38.302851 | D19: (5.5 + 10 x volume term) x complexity
A20: Largest rank allowed | B20: =MAX(32,MIN(256,16*LOG(MAX(2,B4),2))) -> 53.15085 | C20: =MAX(32,MIN(256,16*LOG(MAX(2,C4),2))) -> 53.15085 | D20: Capped by dataset size
A21: Plain rank (unrounded) | B21: =MAX(8,MIN(B19,B20)) -> 38.302851 | C21: 38.302851 | D21: Capacity limited by the cap
A22: Plain planner scale | B22: =ROUND(MAX(0.2,MIN(0.3+(B9-0.6)*0.25,0.5)),2) -> 0.47 | C22: 0.47 | D22: 0.20 to 0.50
A23: Plain timing loss weight | B23: =ROUND(MAX(0.05,MIN(0.08+B12*0.04,0.15)),2) -> 0.11 | C23: 0.12 | D23: 0.05 to 0.15
A24: Plain caption dropout | B24: =IF(OR(B8="Yes",B4<15),0.5,0.35) -> 0.5 | C24: 0.5 | D24: 0.50 for clips or fewer than 15 tracks, else 0.35
A26: Rank multiplier (feedback) | B26: =IF(Calculator!B21="Overcooked",0.75,IF(Calculator!B21="Weak",1.25,1))*IF(Calculator!B22="Weak",1.2,1) -> 1 | D26: Instruments and vocals feedback
A27: Learning-rate multiplier (feedback) | B27: =IF(Calculator!B21="Weak",1.15,1)*IF(Calculator!B22="Overcooked",0.85,1) -> 1 | D27: Instruments Weak x1.15, vocals Overcooked x0.85
A28: Any Overcooked? (1 = yes) | B28: =IF(OR(Calculator!B21="Overcooked",Calculator!B22="Overcooked"),1,0) -> 0 | D28: Forces caption dropout to at least 0.50
A29: Extra decay share (feedback) | B29: =IF(Calculator!B21="Overcooked",0.05,0) -> 0 | D29: Instruments Overcooked adds 5%
A30: Calibration on? (1 = yes) | B30: =IF(Calculator!B27="Yes",1,0) -> 1 | D30: From the Calculator sheet
A31: Calibration: learning-rate factor | B31: =IF(AND(B30=1,ISNUMBER(Engine!F2)),Engine!F2,1) -> 1.1491791 | D31: 1 when off or not entered
A32: Calibration: rank factor | B32: =IF(AND(B30=1,ISNUMBER(Engine!F3)),Engine!F3,1) -> 1.6708939
A33: Calibration: alpha / rank | B33: =IF(AND(B30=1,ISNUMBER(Engine!F9)),Engine!F9,1) -> 1
A34: Calibration: timing factor | B34: =IF(AND(B30=1,ISNUMBER(Engine!F5)),Engine!F5,1) -> 1
A35: Calibration: planner factor | B35: =IF(AND(B30=1,ISNUMBER(Engine!F6)),Engine!F6,1) -> 1
A36: Calibration: dropout shift | B36: =IF(AND(B30=1,ISNUMBER(Engine!F7)),Engine!F7,0) -> 0
A37: Calibration: decay share | B37: =IF(AND(B30=1,ISNUMBER(Engine!F8)),Engine!F8,"") -> 0.36842105 | D37: Blank when off or not entered
A38: Calibration steps available? (1 = yes) | B38: =IF(B30=1,1,0) -> 1
A39: Calibration: steps factor | B39: =IF(B38=1,Engine!F4,1) -> 0.62295082
A40: Calibration: decay shape | B40: =IF(B30=1,Engine!E15,"") -> Cosine
A41: Decay share of the run | B41: =IF(ISNUMBER(B37),B37,0.4)+B29 -> 0.36842105 | D41: 40% by default
...
